[2025-10-19T16:33:51.914+0000] {local_task_job_runner.py:120} INFO - ::group::Pre task execution logs
[2025-10-19T16:33:51.944+0000] {taskinstance.py:2076} INFO - Dependencies all met for dep_context=non-requeueable deps ti=<TaskInstance: airbnb_data_pipeline.load manual__2025-10-19T16:33:46.517974+00:00 [queued]>
[2025-10-19T16:33:51.952+0000] {taskinstance.py:2076} INFO - Dependencies all met for dep_context=requeueable deps ti=<TaskInstance: airbnb_data_pipeline.load manual__2025-10-19T16:33:46.517974+00:00 [queued]>
[2025-10-19T16:33:51.954+0000] {taskinstance.py:2306} INFO - Starting attempt 1 of 2
[2025-10-19T16:33:51.966+0000] {taskinstance.py:2330} INFO - Executing <Task(BashOperator): load> on 2025-10-19 16:33:46.517974+00:00
[2025-10-19T16:33:51.972+0000] {standard_task_runner.py:90} INFO - Running: ['***', 'tasks', 'run', 'airbnb_data_pipeline', 'load', 'manual__2025-10-19T16:33:46.517974+00:00', '--job-id', '6', '--raw', '--subdir', 'DAGS_FOLDER/airbnb_pipeline_dag.py', '--cfg-path', '/tmp/tmpx0zmhnfp']
[2025-10-19T16:33:51.974+0000] {logging_mixin.py:188} WARNING - /home/***/.local/lib/python3.12/site-packages/***/task/task_runner/standard_task_runner.py:61 DeprecationWarning: This process (pid=431) is multi-threaded, use of fork() may lead to deadlocks in the child.
[2025-10-19T16:33:51.974+0000] {standard_task_runner.py:91} INFO - Job 6: Subtask load
[2025-10-19T16:33:51.975+0000] {standard_task_runner.py:63} INFO - Started process 432 to run task
[2025-10-19T16:33:52.038+0000] {task_command.py:426} INFO - Running <TaskInstance: airbnb_data_pipeline.load manual__2025-10-19T16:33:46.517974+00:00 [running]> on host 89568661f918
[2025-10-19T16:33:52.119+0000] {taskinstance.py:2648} INFO - Exporting env vars: AIRFLOW_CTX_DAG_OWNER='***' AIRFLOW_CTX_DAG_ID='airbnb_data_pipeline' AIRFLOW_CTX_TASK_ID='load' AIRFLOW_CTX_EXECUTION_DATE='2025-10-19T16:33:46.517974+00:00' AIRFLOW_CTX_TRY_NUMBER='1' AIRFLOW_CTX_DAG_RUN_ID='manual__2025-10-19T16:33:46.517974+00:00'
[2025-10-19T16:33:52.120+0000] {taskinstance.py:430} INFO - ::endgroup::
[2025-10-19T16:33:52.142+0000] {subprocess.py:63} INFO - Tmp dir root location: /tmp
[2025-10-19T16:33:52.143+0000] {subprocess.py:75} INFO - Running command: ['/usr/bin/bash', '-c', 'python /opt/***/scripts/load.py']
[2025-10-19T16:33:52.151+0000] {subprocess.py:86} INFO - Output:
[2025-10-19T16:33:53.162+0000] {subprocess.py:93} INFO - [load] Connecting to warehouse
[2025-10-19T16:33:53.163+0000] {subprocess.py:93} INFO - Traceback (most recent call last):
[2025-10-19T16:33:53.163+0000] {subprocess.py:93} INFO -   File "/home/***/.local/lib/python3.12/site-packages/sqlalchemy/engine/base.py", line 3371, in _wrap_pool_connect
[2025-10-19T16:33:53.164+0000] {subprocess.py:93} INFO -     return fn()
[2025-10-19T16:33:53.164+0000] {subprocess.py:93} INFO -            ^^^^
[2025-10-19T16:33:53.165+0000] {subprocess.py:93} INFO -   File "/home/***/.local/lib/python3.12/site-packages/sqlalchemy/pool/base.py", line 327, in connect
[2025-10-19T16:33:53.165+0000] {subprocess.py:93} INFO -     return _ConnectionFairy._checkout(self)
[2025-10-19T16:33:53.166+0000] {subprocess.py:93} INFO -            ^^^^^^^^^^^^^^^^^^^^^^^^^^^^^^^^
[2025-10-19T16:33:53.166+0000] {subprocess.py:93} INFO -   File "/home/***/.local/lib/python3.12/site-packages/sqlalchemy/pool/base.py", line 894, in _checkout
[2025-10-19T16:33:53.167+0000] {subprocess.py:93} INFO -     fairy = _ConnectionRecord.checkout(pool)
[2025-10-19T16:33:53.167+0000] {subprocess.py:93} INFO -             ^^^^^^^^^^^^^^^^^^^^^^^^^^^^^^^^
[2025-10-19T16:33:53.167+0000] {subprocess.py:93} INFO -   File "/home/***/.local/lib/python3.12/site-packages/sqlalchemy/pool/base.py", line 493, in checkout
[2025-10-19T16:33:53.168+0000] {subprocess.py:93} INFO -     rec = pool._do_get()
[2025-10-19T16:33:53.168+0000] {subprocess.py:93} INFO -           ^^^^^^^^^^^^^^
[2025-10-19T16:33:53.169+0000] {subprocess.py:93} INFO -   File "/home/***/.local/lib/python3.12/site-packages/sqlalchemy/pool/impl.py", line 145, in _do_get
[2025-10-19T16:33:53.169+0000] {subprocess.py:93} INFO -     with util.safe_reraise():
[2025-10-19T16:33:53.169+0000] {subprocess.py:93} INFO -   File "/home/***/.local/lib/python3.12/site-packages/sqlalchemy/util/langhelpers.py", line 70, in __exit__
[2025-10-19T16:33:53.170+0000] {subprocess.py:93} INFO -     compat.raise_(
[2025-10-19T16:33:53.170+0000] {subprocess.py:93} INFO -   File "/home/***/.local/lib/python3.12/site-packages/sqlalchemy/util/compat.py", line 211, in raise_
[2025-10-19T16:33:53.170+0000] {subprocess.py:93} INFO -     raise exception
[2025-10-19T16:33:53.170+0000] {subprocess.py:93} INFO -   File "/home/***/.local/lib/python3.12/site-packages/sqlalchemy/pool/impl.py", line 143, in _do_get
[2025-10-19T16:33:53.171+0000] {subprocess.py:93} INFO -     return self._create_connection()
[2025-10-19T16:33:53.171+0000] {subprocess.py:93} INFO -            ^^^^^^^^^^^^^^^^^^^^^^^^^
[2025-10-19T16:33:53.171+0000] {subprocess.py:93} INFO -   File "/home/***/.local/lib/python3.12/site-packages/sqlalchemy/pool/base.py", line 273, in _create_connection
[2025-10-19T16:33:53.171+0000] {subprocess.py:93} INFO -     return _ConnectionRecord(self)
[2025-10-19T16:33:53.172+0000] {subprocess.py:93} INFO -            ^^^^^^^^^^^^^^^^^^^^^^^
[2025-10-19T16:33:53.172+0000] {subprocess.py:93} INFO -   File "/home/***/.local/lib/python3.12/site-packages/sqlalchemy/pool/base.py", line 388, in __init__
[2025-10-19T16:33:53.172+0000] {subprocess.py:93} INFO -     self.__connect()
[2025-10-19T16:33:53.172+0000] {subprocess.py:93} INFO -   File "/home/***/.local/lib/python3.12/site-packages/sqlalchemy/pool/base.py", line 690, in __connect
[2025-10-19T16:33:53.172+0000] {subprocess.py:93} INFO -     with util.safe_reraise():
[2025-10-19T16:33:53.173+0000] {subprocess.py:93} INFO -   File "/home/***/.local/lib/python3.12/site-packages/sqlalchemy/util/langhelpers.py", line 70, in __exit__
[2025-10-19T16:33:53.173+0000] {subprocess.py:93} INFO -     compat.raise_(
[2025-10-19T16:33:53.173+0000] {subprocess.py:93} INFO -   File "/home/***/.local/lib/python3.12/site-packages/sqlalchemy/util/compat.py", line 211, in raise_
[2025-10-19T16:33:53.173+0000] {subprocess.py:93} INFO -     raise exception
[2025-10-19T16:33:53.173+0000] {subprocess.py:93} INFO -   File "/home/***/.local/lib/python3.12/site-packages/sqlalchemy/pool/base.py", line 686, in __connect
[2025-10-19T16:33:53.174+0000] {subprocess.py:93} INFO -     self.dbapi_connection = connection = pool._invoke_creator(self)
[2025-10-19T16:33:53.174+0000] {subprocess.py:93} INFO -                                          ^^^^^^^^^^^^^^^^^^^^^^^^^^
[2025-10-19T16:33:53.174+0000] {subprocess.py:93} INFO -   File "/home/***/.local/lib/python3.12/site-packages/sqlalchemy/engine/create.py", line 574, in connect
[2025-10-19T16:33:53.174+0000] {subprocess.py:93} INFO -     return dialect.connect(*cargs, **cparams)
[2025-10-19T16:33:53.175+0000] {subprocess.py:93} INFO -            ^^^^^^^^^^^^^^^^^^^^^^^^^^^^^^^^^^
[2025-10-19T16:33:53.175+0000] {subprocess.py:93} INFO -   File "/home/***/.local/lib/python3.12/site-packages/sqlalchemy/engine/default.py", line 598, in connect
[2025-10-19T16:33:53.175+0000] {subprocess.py:93} INFO -     return self.dbapi.connect(*cargs, **cparams)
[2025-10-19T16:33:53.175+0000] {subprocess.py:93} INFO -            ^^^^^^^^^^^^^^^^^^^^^^^^^^^^^^^^^^^^^
[2025-10-19T16:33:53.176+0000] {subprocess.py:93} INFO -   File "/home/***/.local/lib/python3.12/site-packages/psycopg2/__init__.py", line 122, in connect
[2025-10-19T16:33:53.176+0000] {subprocess.py:93} INFO -     conn = _connect(dsn, connection_factory=connection_factory, **kwasync)
[2025-10-19T16:33:53.176+0000] {subprocess.py:93} INFO -            ^^^^^^^^^^^^^^^^^^^^^^^^^^^^^^^^^^^^^^^^^^^^^^^^^^^^^^^^^^^^^^^
[2025-10-19T16:33:53.176+0000] {subprocess.py:93} INFO - psycopg2.OperationalError: connection to server at "warehouse-db" (172.18.0.3), port 5433 failed: Connection refused
[2025-10-19T16:33:53.176+0000] {subprocess.py:93} INFO - 	Is the server running on that host and accepting TCP/IP connections?
[2025-10-19T16:33:53.177+0000] {subprocess.py:93} INFO - 
[2025-10-19T16:33:53.177+0000] {subprocess.py:93} INFO - 
[2025-10-19T16:33:53.177+0000] {subprocess.py:93} INFO - The above exception was the direct cause of the following exception:
[2025-10-19T16:33:53.177+0000] {subprocess.py:93} INFO - 
[2025-10-19T16:33:53.178+0000] {subprocess.py:93} INFO - Traceback (most recent call last):
[2025-10-19T16:33:53.178+0000] {subprocess.py:93} INFO -   File "/opt/***/scripts/load.py", line 31, in <module>
[2025-10-19T16:33:53.178+0000] {subprocess.py:93} INFO -     load()
[2025-10-19T16:33:53.178+0000] {subprocess.py:93} INFO -   File "/opt/***/scripts/load.py", line 16, in load
[2025-10-19T16:33:53.179+0000] {subprocess.py:93} INFO -     with engine.begin() as conn:
[2025-10-19T16:33:53.179+0000] {subprocess.py:93} INFO -   File "/usr/local/lib/python3.12/contextlib.py", line 137, in __enter__
[2025-10-19T16:33:53.179+0000] {subprocess.py:93} INFO -     return next(self.gen)
[2025-10-19T16:33:53.179+0000] {subprocess.py:93} INFO -            ^^^^^^^^^^^^^^
[2025-10-19T16:33:53.179+0000] {subprocess.py:93} INFO -   File "/home/***/.local/lib/python3.12/site-packages/sqlalchemy/future/engine.py", line 385, in begin
[2025-10-19T16:33:53.180+0000] {subprocess.py:93} INFO -     with self.connect() as conn:
[2025-10-19T16:33:53.180+0000] {subprocess.py:93} INFO -          ^^^^^^^^^^^^^^
[2025-10-19T16:33:53.180+0000] {subprocess.py:93} INFO -   File "/home/***/.local/lib/python3.12/site-packages/sqlalchemy/future/engine.py", line 412, in connect
[2025-10-19T16:33:53.180+0000] {subprocess.py:93} INFO -     return super(Engine, self).connect()
[2025-10-19T16:33:53.181+0000] {subprocess.py:93} INFO -            ^^^^^^^^^^^^^^^^^^^^^^^^^^^^^
[2025-10-19T16:33:53.181+0000] {subprocess.py:93} INFO -   File "/home/***/.local/lib/python3.12/site-packages/sqlalchemy/engine/base.py", line 3325, in connect
[2025-10-19T16:33:53.181+0000] {subprocess.py:93} INFO -     return self._connection_cls(self, close_with_result=close_with_result)
[2025-10-19T16:33:53.182+0000] {subprocess.py:93} INFO -            ^^^^^^^^^^^^^^^^^^^^^^^^^^^^^^^^^^^^^^^^^^^^^^^^^^^^^^^^^^^^^^^
[2025-10-19T16:33:53.182+0000] {subprocess.py:93} INFO -   File "/home/***/.local/lib/python3.12/site-packages/sqlalchemy/engine/base.py", line 96, in __init__
[2025-10-19T16:33:53.182+0000] {subprocess.py:93} INFO -     else engine.raw_connection()
[2025-10-19T16:33:53.182+0000] {subprocess.py:93} INFO -          ^^^^^^^^^^^^^^^^^^^^^^^
[2025-10-19T16:33:53.183+0000] {subprocess.py:93} INFO -   File "/home/***/.local/lib/python3.12/site-packages/sqlalchemy/engine/base.py", line 3404, in raw_connection
[2025-10-19T16:33:53.183+0000] {subprocess.py:93} INFO -     return self._wrap_pool_connect(self.pool.connect, _connection)
[2025-10-19T16:33:53.183+0000] {subprocess.py:93} INFO -            ^^^^^^^^^^^^^^^^^^^^^^^^^^^^^^^^^^^^^^^^^^^^^^^^^^^^^^^
[2025-10-19T16:33:53.183+0000] {subprocess.py:93} INFO -   File "/home/***/.local/lib/python3.12/site-packages/sqlalchemy/engine/base.py", line 3374, in _wrap_pool_connect
[2025-10-19T16:33:53.184+0000] {subprocess.py:93} INFO -     Connection._handle_dbapi_exception_noconnection(
[2025-10-19T16:33:53.184+0000] {subprocess.py:93} INFO -   File "/home/***/.local/lib/python3.12/site-packages/sqlalchemy/engine/base.py", line 2208, in _handle_dbapi_exception_noconnection
[2025-10-19T16:33:53.184+0000] {subprocess.py:93} INFO -     util.raise_(
[2025-10-19T16:33:53.184+0000] {subprocess.py:93} INFO -   File "/home/***/.local/lib/python3.12/site-packages/sqlalchemy/util/compat.py", line 211, in raise_
[2025-10-19T16:33:53.185+0000] {subprocess.py:93} INFO -     raise exception
[2025-10-19T16:33:53.185+0000] {subprocess.py:93} INFO -   File "/home/***/.local/lib/python3.12/site-packages/sqlalchemy/engine/base.py", line 3371, in _wrap_pool_connect
[2025-10-19T16:33:53.185+0000] {subprocess.py:93} INFO -     return fn()
[2025-10-19T16:33:53.186+0000] {subprocess.py:93} INFO -            ^^^^
[2025-10-19T16:33:53.186+0000] {subprocess.py:93} INFO -   File "/home/***/.local/lib/python3.12/site-packages/sqlalchemy/pool/base.py", line 327, in connect
[2025-10-19T16:33:53.186+0000] {subprocess.py:93} INFO -     return _ConnectionFairy._checkout(self)
[2025-10-19T16:33:53.186+0000] {subprocess.py:93} INFO -            ^^^^^^^^^^^^^^^^^^^^^^^^^^^^^^^^
[2025-10-19T16:33:53.186+0000] {subprocess.py:93} INFO -   File "/home/***/.local/lib/python3.12/site-packages/sqlalchemy/pool/base.py", line 894, in _checkout
[2025-10-19T16:33:53.187+0000] {subprocess.py:93} INFO -     fairy = _ConnectionRecord.checkout(pool)
[2025-10-19T16:33:53.187+0000] {subprocess.py:93} INFO -             ^^^^^^^^^^^^^^^^^^^^^^^^^^^^^^^^
[2025-10-19T16:33:53.187+0000] {subprocess.py:93} INFO -   File "/home/***/.local/lib/python3.12/site-packages/sqlalchemy/pool/base.py", line 493, in checkout
[2025-10-19T16:33:53.187+0000] {subprocess.py:93} INFO -     rec = pool._do_get()
[2025-10-19T16:33:53.188+0000] {subprocess.py:93} INFO -           ^^^^^^^^^^^^^^
[2025-10-19T16:33:53.188+0000] {subprocess.py:93} INFO -   File "/home/***/.local/lib/python3.12/site-packages/sqlalchemy/pool/impl.py", line 145, in _do_get
[2025-10-19T16:33:53.188+0000] {subprocess.py:93} INFO -     with util.safe_reraise():
[2025-10-19T16:33:53.188+0000] {subprocess.py:93} INFO -   File "/home/***/.local/lib/python3.12/site-packages/sqlalchemy/util/langhelpers.py", line 70, in __exit__
[2025-10-19T16:33:53.189+0000] {subprocess.py:93} INFO -     compat.raise_(
[2025-10-19T16:33:53.189+0000] {subprocess.py:93} INFO -   File "/home/***/.local/lib/python3.12/site-packages/sqlalchemy/util/compat.py", line 211, in raise_
[2025-10-19T16:33:53.189+0000] {subprocess.py:93} INFO -     raise exception
[2025-10-19T16:33:53.189+0000] {subprocess.py:93} INFO -   File "/home/***/.local/lib/python3.12/site-packages/sqlalchemy/pool/impl.py", line 143, in _do_get
[2025-10-19T16:33:53.190+0000] {subprocess.py:93} INFO -     return self._create_connection()
[2025-10-19T16:33:53.190+0000] {subprocess.py:93} INFO -            ^^^^^^^^^^^^^^^^^^^^^^^^^
[2025-10-19T16:33:53.190+0000] {subprocess.py:93} INFO -   File "/home/***/.local/lib/python3.12/site-packages/sqlalchemy/pool/base.py", line 273, in _create_connection
[2025-10-19T16:33:53.190+0000] {subprocess.py:93} INFO -     return _ConnectionRecord(self)
[2025-10-19T16:33:53.191+0000] {subprocess.py:93} INFO -            ^^^^^^^^^^^^^^^^^^^^^^^
[2025-10-19T16:33:53.191+0000] {subprocess.py:93} INFO -   File "/home/***/.local/lib/python3.12/site-packages/sqlalchemy/pool/base.py", line 388, in __init__
[2025-10-19T16:33:53.191+0000] {subprocess.py:93} INFO -     self.__connect()
[2025-10-19T16:33:53.191+0000] {subprocess.py:93} INFO -   File "/home/***/.local/lib/python3.12/site-packages/sqlalchemy/pool/base.py", line 690, in __connect
[2025-10-19T16:33:53.191+0000] {subprocess.py:93} INFO -     with util.safe_reraise():
[2025-10-19T16:33:53.192+0000] {subprocess.py:93} INFO -   File "/home/***/.local/lib/python3.12/site-packages/sqlalchemy/util/langhelpers.py", line 70, in __exit__
[2025-10-19T16:33:53.192+0000] {subprocess.py:93} INFO -     compat.raise_(
[2025-10-19T16:33:53.192+0000] {subprocess.py:93} INFO -   File "/home/***/.local/lib/python3.12/site-packages/sqlalchemy/util/compat.py", line 211, in raise_
[2025-10-19T16:33:53.192+0000] {subprocess.py:93} INFO -     raise exception
[2025-10-19T16:33:53.192+0000] {subprocess.py:93} INFO -   File "/home/***/.local/lib/python3.12/site-packages/sqlalchemy/pool/base.py", line 686, in __connect
[2025-10-19T16:33:53.193+0000] {subprocess.py:93} INFO -     self.dbapi_connection = connection = pool._invoke_creator(self)
[2025-10-19T16:33:53.193+0000] {subprocess.py:93} INFO -                                          ^^^^^^^^^^^^^^^^^^^^^^^^^^
[2025-10-19T16:33:53.193+0000] {subprocess.py:93} INFO -   File "/home/***/.local/lib/python3.12/site-packages/sqlalchemy/engine/create.py", line 574, in connect
[2025-10-19T16:33:53.193+0000] {subprocess.py:93} INFO -     return dialect.connect(*cargs, **cparams)
[2025-10-19T16:33:53.194+0000] {subprocess.py:93} INFO -            ^^^^^^^^^^^^^^^^^^^^^^^^^^^^^^^^^^
[2025-10-19T16:33:53.194+0000] {subprocess.py:93} INFO -   File "/home/***/.local/lib/python3.12/site-packages/sqlalchemy/engine/default.py", line 598, in connect
[2025-10-19T16:33:53.194+0000] {subprocess.py:93} INFO -     return self.dbapi.connect(*cargs, **cparams)
[2025-10-19T16:33:53.194+0000] {subprocess.py:93} INFO -            ^^^^^^^^^^^^^^^^^^^^^^^^^^^^^^^^^^^^^
[2025-10-19T16:33:53.194+0000] {subprocess.py:93} INFO -   File "/home/***/.local/lib/python3.12/site-packages/psycopg2/__init__.py", line 122, in connect
[2025-10-19T16:33:53.195+0000] {subprocess.py:93} INFO -     conn = _connect(dsn, connection_factory=connection_factory, **kwasync)
[2025-10-19T16:33:53.195+0000] {subprocess.py:93} INFO -            ^^^^^^^^^^^^^^^^^^^^^^^^^^^^^^^^^^^^^^^^^^^^^^^^^^^^^^^^^^^^^^^
[2025-10-19T16:33:53.195+0000] {subprocess.py:93} INFO - sqlalchemy.exc.OperationalError: (psycopg2.OperationalError) connection to server at "warehouse-db" (172.18.0.3), port 5433 failed: Connection refused
[2025-10-19T16:33:53.195+0000] {subprocess.py:93} INFO - 	Is the server running on that host and accepting TCP/IP connections?
[2025-10-19T16:33:53.196+0000] {subprocess.py:93} INFO - 
[2025-10-19T16:33:53.196+0000] {subprocess.py:93} INFO - (Background on this error at: https://sqlalche.me/e/14/e3q8)
[2025-10-19T16:33:53.255+0000] {subprocess.py:97} INFO - Command exited with return code 1
[2025-10-19T16:33:53.256+0000] {taskinstance.py:441} INFO - ::group::Post task execution logs
[2025-10-19T16:33:53.267+0000] {taskinstance.py:2905} ERROR - Task failed with exception
Traceback (most recent call last):
  File "/home/airflow/.local/lib/python3.12/site-packages/airflow/models/taskinstance.py", line 465, in _execute_task
    result = _execute_callable(context=context, **execute_callable_kwargs)
             ^^^^^^^^^^^^^^^^^^^^^^^^^^^^^^^^^^^^^^^^^^^^^^^^^^^^^^^^^^^^^
  File "/home/airflow/.local/lib/python3.12/site-packages/airflow/models/taskinstance.py", line 432, in _execute_callable
    return execute_callable(context=context, **execute_callable_kwargs)
           ^^^^^^^^^^^^^^^^^^^^^^^^^^^^^^^^^^^^^^^^^^^^^^^^^^^^^^^^^^^^
  File "/home/airflow/.local/lib/python3.12/site-packages/airflow/models/baseoperator.py", line 401, in wrapper
    return func(self, *args, **kwargs)
           ^^^^^^^^^^^^^^^^^^^^^^^^^^^
  File "/home/airflow/.local/lib/python3.12/site-packages/airflow/operators/bash.py", line 243, in execute
    raise AirflowException(
airflow.exceptions.AirflowException: Bash command failed. The command returned a non-zero exit code 1.
[2025-10-19T16:33:53.271+0000] {taskinstance.py:1206} INFO - Marking task as UP_FOR_RETRY. dag_id=airbnb_data_pipeline, task_id=load, run_id=manual__2025-10-19T16:33:46.517974+00:00, execution_date=20251019T163346, start_date=20251019T163351, end_date=20251019T163353
[2025-10-19T16:33:53.288+0000] {standard_task_runner.py:110} ERROR - Failed to execute job 6 for task load (Bash command failed. The command returned a non-zero exit code 1.; 432)
[2025-10-19T16:33:53.322+0000] {local_task_job_runner.py:240} INFO - Task exited with return code 1
[2025-10-19T16:33:53.338+0000] {taskinstance.py:3503} INFO - 0 downstream tasks scheduled from follow-on schedule check
[2025-10-19T16:33:53.341+0000] {local_task_job_runner.py:222} INFO - ::endgroup::
